
## panic

当函数发生panic时，它会终止运行，在执行完所有的延迟函数后，程序控制返回到该函数的调用方。这样的过程会一直持续下去，直到当前协程的所有函数都返回退出，然后程序会打印出panic信息，接着打印出堆栈跟踪，最后程序终止。

```go
func fullName(firstName *string, lastName *string) {
	defer fmt.Println("deferred call in fullName")
	if firstName == nil {
		panic("runtime error: first name cannot be nil")
	}
	if lastName == nil {
		panic("runtime error: last name cannot be nil")
	}
	fmt.Printf("%s %s\n", *firstName, *lastName)
	fmt.Println("returned normally from fullName")
}

func main() {
	firstName := "Elon"
	fullName(&firstName, nil)
	fmt.Println("returned normally from main")
}
//返回值:
deferred call in fullName
panic: runtime error: last name cannot be nil

goroutine 1 [running]:
main.fullName(0xc000089f30, 0x0)
	/error/demo8.go:16 +0x255
main.main()
	/error/demo8.go:24 +0x54
```

## recover

`recover`是一个内建函数，用于重新获得`panic`协程的控制。只有在延迟函数的内部，调用`recover`才有效

```go
func fullName2(firstName *string, lastName *string) {
	defer recoverName()
	if firstName == nil {
		panic("runtime error: first name cannot be nil")
	}
	if lastName == nil {
		panic("runtime error: last name cannot be nil")
	}
	fmt.Printf("%s %s\n", *firstName, *lastName)
	fmt.Println("returned normally from fullName")
}

func recoverName() {
	if r:=recover();r!=nil{
		fmt.Println("recovered from ", r)
	}
}

func main() {
	defer fmt.Println("deferred call in main")
	firstName := "Elon"
	fullName2(&firstName, nil)
	fmt.Println("returned normally from main")
}
```

只有在相同的Go协程中调用`recover`才有用。`recover`不能恢复一个不同协程的`panic`

```go
func recovery() {
	if r := recover(); r != nil {
		fmt.Println("recovered:", r)
	}
}

func a() {
	defer recovery()
	fmt.Println("Inside A")
	go b()
	time.Sleep(1 * time.Second)
}

func b() {
	fmt.Println("Inside B")
	panic("oh! B panicked")
}

func main() {
	a()
	fmt.Println("normally returned from main")
}

//输出
Inside A
Inside B
panic: oh! B panicked

goroutine 6 [running]:
main.b()
	/error/demo10.go:25 +0x9c
created by main.a
	/error/demo10.go:19 +0xd3
```

## defer中抛出panic

```go
func TestDemo1B(t *testing.T) {
	defer func() {
		if err := recover(); err != nil {
			fmt.Println("++++")
			f := err.(func() string)
			fmt.Println(err, f(), reflect.TypeOf(err).Kind().String())
		} else {
			fmt.Println("fatal")
		}
	}()

	defer func() {
		panic(func() string {
			return "defer panic"
		})
	}()
	panic("panic")
}

//输出
++++
0x5061f0 defer panic func
```